2019-11-16 22:16:38,238 INFO: Microblog startup [in D:\Martin\projects\microblog\app\__init__.py:45]
2019-11-16 22:17:06,236 ERROR: Exception on /edit_profile [POST] [in C:\anaconda\envs\microblog\lib\site-packages\flask\app.py:1891]
Traceback (most recent call last):
  File "C:\anaconda\envs\microblog\lib\site-packages\sqlalchemy\engine\base.py", line 1249, in _execute_context
    cursor, statement, parameters, context
  File "C:\anaconda\envs\microblog\lib\site-packages\sqlalchemy\engine\default.py", line 580, in do_execute
    cursor.execute(statement, parameters)
sqlite3.IntegrityError: UNIQUE constraint failed: user.username

The above exception was the direct cause of the following exception:

Traceback (most recent call last):
  File "C:\anaconda\envs\microblog\lib\site-packages\flask\app.py", line 2446, in wsgi_app
    response = self.full_dispatch_request()
  File "C:\anaconda\envs\microblog\lib\site-packages\flask\app.py", line 1951, in full_dispatch_request
    rv = self.handle_user_exception(e)
  File "C:\anaconda\envs\microblog\lib\site-packages\flask\app.py", line 1820, in handle_user_exception
    reraise(exc_type, exc_value, tb)
  File "C:\anaconda\envs\microblog\lib\site-packages\flask\_compat.py", line 39, in reraise
    raise value
  File "C:\anaconda\envs\microblog\lib\site-packages\flask\app.py", line 1949, in full_dispatch_request
    rv = self.dispatch_request()
  File "C:\anaconda\envs\microblog\lib\site-packages\flask\app.py", line 1935, in dispatch_request
    return self.view_functions[rule.endpoint](**req.view_args)
  File "C:\anaconda\envs\microblog\lib\site-packages\flask_login\utils.py", line 261, in decorated_view
    return func(*args, **kwargs)
  File "D:\Martin\projects\microblog\app\routes.py", line 93, in edit_profile
    db.session.commit()
  File "C:\anaconda\envs\microblog\lib\site-packages\sqlalchemy\orm\scoping.py", line 162, in do
    return getattr(self.registry(), name)(*args, **kwargs)
  File "C:\anaconda\envs\microblog\lib\site-packages\sqlalchemy\orm\session.py", line 1027, in commit
    self.transaction.commit()
  File "C:\anaconda\envs\microblog\lib\site-packages\sqlalchemy\orm\session.py", line 494, in commit
    self._prepare_impl()
  File "C:\anaconda\envs\microblog\lib\site-packages\sqlalchemy\orm\session.py", line 473, in _prepare_impl
    self.session.flush()
  File "C:\anaconda\envs\microblog\lib\site-packages\sqlalchemy\orm\session.py", line 2470, in flush
    self._flush(objects)
  File "C:\anaconda\envs\microblog\lib\site-packages\sqlalchemy\orm\session.py", line 2608, in _flush
    transaction.rollback(_capture_exception=True)
  File "C:\anaconda\envs\microblog\lib\site-packages\sqlalchemy\util\langhelpers.py", line 68, in __exit__
    compat.reraise(exc_type, exc_value, exc_tb)
  File "C:\anaconda\envs\microblog\lib\site-packages\sqlalchemy\util\compat.py", line 153, in reraise
    raise value
  File "C:\anaconda\envs\microblog\lib\site-packages\sqlalchemy\orm\session.py", line 2568, in _flush
    flush_context.execute()
  File "C:\anaconda\envs\microblog\lib\site-packages\sqlalchemy\orm\unitofwork.py", line 422, in execute
    rec.execute(self)
  File "C:\anaconda\envs\microblog\lib\site-packages\sqlalchemy\orm\unitofwork.py", line 589, in execute
    uow,
  File "C:\anaconda\envs\microblog\lib\site-packages\sqlalchemy\orm\persistence.py", line 236, in save_obj
    update,
  File "C:\anaconda\envs\microblog\lib\site-packages\sqlalchemy\orm\persistence.py", line 996, in _emit_update_statements
    statement, multiparams
  File "C:\anaconda\envs\microblog\lib\site-packages\sqlalchemy\engine\base.py", line 988, in execute
    return meth(self, multiparams, params)
  File "C:\anaconda\envs\microblog\lib\site-packages\sqlalchemy\sql\elements.py", line 287, in _execute_on_connection
    return connection._execute_clauseelement(self, multiparams, params)
  File "C:\anaconda\envs\microblog\lib\site-packages\sqlalchemy\engine\base.py", line 1107, in _execute_clauseelement
    distilled_params,
  File "C:\anaconda\envs\microblog\lib\site-packages\sqlalchemy\engine\base.py", line 1253, in _execute_context
    e, statement, parameters, cursor, context
  File "C:\anaconda\envs\microblog\lib\site-packages\sqlalchemy\engine\base.py", line 1473, in _handle_dbapi_exception
    util.raise_from_cause(sqlalchemy_exception, exc_info)
  File "C:\anaconda\envs\microblog\lib\site-packages\sqlalchemy\util\compat.py", line 398, in raise_from_cause
    reraise(type(exception), exception, tb=exc_tb, cause=cause)
  File "C:\anaconda\envs\microblog\lib\site-packages\sqlalchemy\util\compat.py", line 152, in reraise
    raise value.with_traceback(tb)
  File "C:\anaconda\envs\microblog\lib\site-packages\sqlalchemy\engine\base.py", line 1249, in _execute_context
    cursor, statement, parameters, context
  File "C:\anaconda\envs\microblog\lib\site-packages\sqlalchemy\engine\default.py", line 580, in do_execute
    cursor.execute(statement, parameters)
sqlalchemy.exc.IntegrityError: (sqlite3.IntegrityError) UNIQUE constraint failed: user.username
[SQL: UPDATE user SET username=?, about_me=? WHERE user.id = ?]
[parameters: ('susan', "I'm a happy camper, actually! Yes, sir! Yes!", 3)]
(Background on this error at: http://sqlalche.me/e/gkpj)
2019-11-16 23:17:26,568 INFO: Microblog startup [in D:\Martin\projects\microblog\app\__init__.py:45]
2019-11-16 23:17:33,510 ERROR: Exception on /edit_profile [GET] [in C:\anaconda\envs\microblog\lib\site-packages\flask\app.py:1891]
Traceback (most recent call last):
  File "C:\anaconda\envs\microblog\lib\site-packages\flask\app.py", line 2446, in wsgi_app
    response = self.full_dispatch_request()
  File "C:\anaconda\envs\microblog\lib\site-packages\flask\app.py", line 1951, in full_dispatch_request
    rv = self.handle_user_exception(e)
  File "C:\anaconda\envs\microblog\lib\site-packages\flask\app.py", line 1820, in handle_user_exception
    reraise(exc_type, exc_value, tb)
  File "C:\anaconda\envs\microblog\lib\site-packages\flask\_compat.py", line 39, in reraise
    raise value
  File "C:\anaconda\envs\microblog\lib\site-packages\flask\app.py", line 1949, in full_dispatch_request
    rv = self.dispatch_request()
  File "C:\anaconda\envs\microblog\lib\site-packages\flask\app.py", line 1935, in dispatch_request
    return self.view_functions[rule.endpoint](**req.view_args)
  File "C:\anaconda\envs\microblog\lib\site-packages\flask_login\utils.py", line 261, in decorated_view
    return func(*args, **kwargs)
  File "D:\Martin\projects\microblog\app\routes.py", line 89, in edit_profile
    form=EditProfileForm()
  File "C:\anaconda\envs\microblog\lib\site-packages\wtforms\form.py", line 212, in __call__
    return type.__call__(cls, *args, **kwargs)
TypeError: __init__() missing 1 required positional argument: 'original_username'
2019-11-16 23:18:21,894 INFO: Microblog startup [in D:\Martin\projects\microblog\app\__init__.py:45]
2019-11-17 18:24:17,747 INFO: Microblog startup [in D:\Martin\projects\microblog\app\__init__.py:45]
2019-11-17 18:24:44,446 INFO: Microblog startup [in D:\Martin\projects\microblog\app\__init__.py:45]
2019-11-22 22:05:01,715 INFO: Microblog startup [in D:\Martin\projects\microblog\app\__init__.py:45]
2019-11-22 22:06:03,960 INFO: Microblog startup [in D:\Martin\projects\microblog\app\__init__.py:45]
2019-11-22 22:07:06,864 INFO: Microblog startup [in D:\Martin\projects\microblog\app\__init__.py:45]
2019-11-22 22:39:04,524 INFO: Microblog startup [in D:\Martin\projects\microblog\app\__init__.py:45]
2019-11-22 22:39:12,785 INFO: Microblog startup [in D:\Martin\projects\microblog\app\__init__.py:45]
2019-11-22 22:59:12,224 INFO: Microblog startup [in D:\Martin\projects\microblog\app\__init__.py:45]
